Workbook

Sheet 00_Cover
B2: Northline Consumer Products
B3: Headcount and staffing forecast · plan, loaded cost, reforecast
B4: Mid-size CPG · ops + supply chain + commercial + G&A · ~280–310 FTE · FY2026
B6: What this file is
B7: A twelve-month headcount plan and reforecast for a fictional CPG company. It rolls opening FTE + hires − exits by department, applies loaded cost and a mid-year merit, and compares the original plan to the latest view (YTD actuals through the as-of month, then forecast).
B9: How to use
B10: 1. Edit yellow cells on 01_Assumptions (departments, loaded cost, attrition, raise, as-of month).
B11: 2. Edit plan hires and other exits on 02_Headcount_Plan. Opening, attrition exits, and ending FTE are formulas.
B12: 3. Read the loaded-cost rollforward and plan vs forecast $ on 03_Cost_Bridge.
B13: 4. Edit forecast hires / other exits on 04_Reforecast; compare latest view vs original plan.
B14: 5. Use 05_Dashboard as the one-pager.
B16: File conventions
... B22: https://github.com/saisiri-bandaru

Sheet 01_Assumptions
B2: Assumptions
B3: Yellow + blue = inputs. Change these; plan, cost, reforecast, and dashboard recalculate.
B5: As-of / toggle month (1 = Jan … 12 = Dec) | C5: 6 | D5: =INDEX({"Jan-26","Feb-26","Mar-26","Apr-26","May-26","Jun-26","Jul-26","Aug-26","Sep-26","Oct-26","Nov-26","Dec-26"},1,C5) | E5: Months ≤ as-of on the reforecast are YTD actuals; months after are forecast.
B6: Merit / raise % | C6: 0.035
B7: Raise effective month (1–12) | C7: 4 | D7: April — loaded cost steps up from this month.
B8: Hire lead time (months) | C8: 2 | D8: Hires are recorded in the start month (already net of lead time). Open reqs are the pipeline.
B10: Department drivers
B11: Department | C11: Opening FTE | D11: Annual loaded cost ($000s) | E11: Annual attrition % | F11: Monthly attrition % | G11: Open reqs (pipeline)
B12: Operations | C12: 120 | D12: 72 | E12: 0.14 | F12: =E12/12 | G12: 4
B13: Supply Chain | C13: 48 | D13: 78 | E13: 0.12 | F13: =E13/12 | G13: 2
B14: Sales | C14: 40 | D14: 128 | E14: 0.16 | F14: =E14/12 | G14: 3
B15: Marketing | C15: 18 | D15: 112 | E15: 0.11 | F15: =E15/12 | G15: 1
B16: Finance | C16: 16 | D16: 118 | E16: 0.08 | F16: =E16/12 | G16: 1
B17: HR | C17: 8 | D17: 96 | E17: 0.1 | F17: =E17/12 | G17: 0
B18: Quality / R&D | C18: 22 | D18: 90 | E18: 0.09 | F18: =E18/12 | G18: 1
B19: G&A / IT | C19: 14 | D19: 108 | E19: 0.07 | F19: =E19/12 | G19: 1
B20: Total | C20: =SUM(C12:C19) | D20: =SUMPRODUCT(C12:C19,D12:D19)/C20 | E20: =SUMPRODUCT(C12:C19,E12:E19)/C20 | F20: =E20/12 | G20: =SUM(G12:G19)
B22: Loaded cost is fully loaded (salary + benefits + taxes + typical bonus). Plant roles sit below corporate / sales.
B23: Monthly attrition used in the plan = annual attrition ÷ 12 (straight-line). Ending FTE is allowed to be fractional for planning.
B24: Company-wide average loaded cost (opening mix) | C24: =D20

Sheet 02_Headcount_Plan
B2: Headcount plan (original)
B3: Hires and other exits are inputs. Opening FTE, attrition exits, total exits, and ending FTE are formulas.
B6: Opening FTE
C7: Jan-26 | D7: Feb-26 | E7: Mar-26 | F7: Apr-26 | G7: May-26 | H7: Jun-26 | I7: Jul-26 | J7: Aug-26 | K7: Sep-26 | L7: Oct-26 | M7: Nov-26 | N7: Dec-26 | O7: FY26
B8: Operations | C8: ='01_Assumptions'!C12 | D8: =C68 | E8: =D68 | F8: =E68 | G8: =F68 | H8: =G68 | I8: =H68 | J8: =I68 | K8: =J68 | ... N8: =M68 | O8: =C8
B9: Supply Chain | C9: ='01_Assumptions'!C13 | D9: =C69 | E9: =D69 | F9: =E69 | G9: =F69 | H9: =G69 | I9: =H69 | J9: =I69 | K9: =J69 | ... N9: =M69 | O9: =C9
B10: Sales | C10: ='01_Assumptions'!C14 | D10: =C70 | E10: =D70 | F10: =E70 | G10: =F70 | H10: =G70 | I10: =H70 | J10: =I70 | K10: =J70 | ... N10: =M70 | O10: =C10
B11: Marketing | C11: ='01_Assumptions'!C15 | D11: =C71 | E11: =D71 | F11: =E71 | G11: =F71 | H11: =G71 | I11: =H71 | J11: =I71 | K11: =J71 | ... N11: =M71 | O11: =C11
B12: Finance | C12: ='01_Assumptions'!C16 | D12: =C72 | E12: =D72 | F12: =E72 | G12: =F72 | H12: =G72 | I12: =H72 | J12: =I72 | K12: =J72 | ... N12: =M72 | O12: =C12
B13: HR | C13: ='01_Assumptions'!C17 | D13: =C73 | E13: =D73 | F13: =E73 | G13: =F73 | H13: =G73 | I13: =H73 | J13: =I73 | K13: =J73 | ... N13: =M73 | O13: =C13
B14: Quality / R&D | C14: ='01_Assumptions'!C18 | D14: =C74 | E14: =D74 | F14: =E74 | G14: =F74 | H14: =G74 | I14: =H74 | J14: =I74 | K14: =J74 | ... N14: =M74 | O14: =C14
B15: G&A / IT | C15: ='01_Assumptions'!C19 | D15: =C75 | E15: =D75 | F15: =E75 | G15: =F75 | H15: =G75 | I15: =H75 | J15: =I75 | K15: =J75 | ... N15: =M75 | O15: =C15
B16: Total | C16: =SUM(C8:C15) | D16: =SUM(D8:D15) | E16: =SUM(E8:E15) | F16: =SUM(F8:F15) | G16: =SUM(G8:G15) | H16: =SUM(H8:H15) | I16: =SUM(I8:I15) | J16: =SUM(J8:J15) | ... O16: =SUM(O8:O15)
B18: Hires (starts) — input
C19: Jan-26 | D19: Feb-26 | E19: Mar-26 | F19: Apr-26 | G19: May-26 | H19: Jun-26 | I19: Jul-26 | J19: Aug-26 | K19: Sep-26 | L19: Oct-26 | M19: Nov-26 | N19: Dec-26 | O19: FY26
B20: Operations | C20: 2 | D20: 1 | E20: 2 | F20: 1 | G20: 2 | H20: 2 | I20: 3 | J20: 2 | K20: 1 | L20: 2 | M20: 1 | N20: 1 | O20: =SUM(C20:N20)
B21: Supply Chain | C21: 1 | D21: 0 | E21: 1 | F21: 1 | G21: 0 | H21: 1 | I21: 1 | J21: 1 | K21: 0 | L21: 1 | M21: 1 | N21: 0 | O21: =SUM(C21:N21)
B22: Sales | C22: 1 | D22: 1 | E22: 0 | F22: 1 | G22: 1 | H22: 0 | I22: 1 | J22: 0 | K22: 1 | L22: 2 | M22: 0 | N22: 1 | O22: =SUM(C22:N22)
B23: Marketing | C23: 0 | D23: 1 | E23: 0 | F23: 0 | G23: 1 | H23: 0 | I23: 0 | J23: 1 | K23: 0 | L23: 0 | M23: 0 | N23: 0 | O23: =SUM(C23:N23)
B24: Finance | C24: 0 | D24: 0 | E24: 1 | F24: 0 | G24: 0 | H24: 0 | I24: 0 | J24: 1 | K24: 0 | L24: 0 | M24: 0 | N24: 0 | O24: =SUM(C24:N24)
B25: HR | C25: 0 | D25: 0 | E25: 0 | F25: 1 | G25: 0 | H25: 0 | I25: 0 | J25: 0 | K25: 0 | L25: 0 | M25: 0 | N25: 0 | O25: =SUM(C25:N25)
B26: Quality / R&D | C26: 0 | D26: 1 | E26: 0 | F26: 0 | G26: 1 | H26: 0 | I26: 1 | J26: 0 | K26: 0 | L26: 0 | M26: 0 | N26: 0 | O26: =SUM(C26:N26)
B27: G&A / IT | C27: 0 | D27: 0 | E27: 0 | F27: 1 | G27: 0 | H27: 0 | I27: 0 | J27: 0 | K27: 0 | L27: 1 | M27: 0 | N27: 0 | O27: =SUM(C27:N27)
B28: Total | C28: =SUM(C20:C27) | D28: =SUM(D20:D27) | E28: =SUM(E20:E27) | F28: =SUM(F20:F27) | G28: =SUM(G20:G27) | H28: =SUM(H20:H27) | I28: =SUM(I20:I27) | J28: =SUM(J20:J27) | ... O28: =SUM(O20:O27)
B30: Modeled attrition exits = ROUND(opening × monthly attrition, 1)
C31: Jan-26 | D31: Feb-26 | E31: Mar-26 | F31: Apr-26 | G31: May-26 | H31: Jun-26 | I31: Jul-26 | J31: Aug-26 | K31: Sep-26 | L31: Oct-26 | M31: Nov-26 | N31: Dec-26 | O31: FY26
B32: Operations | C32: =ROUND(C8*'01_Assumptions'!$F$12,1) | D32: =ROUND(D8*'01_Assumptions'!$F$12,1) | E32: =ROUND(E8*'01_Assumptions'!$F$12,1) | F32: =ROUND(F8*'01_Assumptions'!$F$12,1) | G32: =ROUND(G8*'01_Assumptions'!$F$12,1) | H32: =ROUND(H8*'01_Assumptions'!$F$12,1) | I32: =ROUND(I8*'01_Assumptions'!$F$12,1) | J32: =ROUND(J8*'01_Assumptions'!$F$12,1) | ... N32: =ROUND(N8*'01_Assumptions'!$F$12,1) | O32: =SUM(C32:N32)
B33: Supply Chain | C33: =ROUND(C9*'01_Assumptions'!$F$13,1) | D33: =ROUND(D9*'01_Assumptions'!$F$13,1) | E33: =ROUND(E9*'01_Assumptions'!$F$13,1) | F33: =ROUND(F9*'01_Assumptions'!$F$13,1) | G33: =ROUND(G9*'01_Assumptions'!$F$13,1) | H33: =ROUND(H9*'01_Assumptions'!$F$13,1) | I33: =ROUND(I9*'01_Assumptions'!$F$13,1) | J33: =ROUND(J9*'01_Assumptions'!$F$13,1) | ... N33: =ROUND(N9*'01_Assumptions'!$F$13,1) | O33: =SUM(C33:N33)
B34: Sales | C34: =ROUND(C10*'01_Assumptions'!$F$14,1) | D34: =ROUND(D10*'01_Assumptions'!$F$14,1) | E34: =ROUND(E10*'01_Assumptions'!$F$14,1) | F34: =ROUND(F10*'01_Assumptions'!$F$14,1) | G34: =ROUND(G10*'01_Assumptions'!$F$14,1) | H34: =ROUND(H10*'01_Assumptions'!$F$14,1) | I34: =ROUND(I10*'01_Assumptions'!$F$14,1) | J34: =ROUND(J10*'01_Assumptions'!$F$14,1) | ... N34: =ROUND(N10*'01_Assumptions'!$F$14,1) | O34: =SUM(C34:N34)
B35: Marketing | C35: =ROUND(C11*'01_Assumptions'!$F$15,1) | D35: =ROUND(D11*'01_Assumptions'!$F$15,1) | E35: =ROUND(E11*'01_Assumptions'!$F$15,1) | F35: =ROUND(F11*'01_Assumptions'!$F$15,1) | G35: =ROUND(G11*'01_Assumptions'!$F$15,1) | H35: =ROUND(H11*'01_Assumptions'!$F$15,1) | I35: =ROUND(I11*'01_Assumptions'!$F$15,1) | J35: =ROUND(J11*'01_Assumptions'!$F$15,1) | ... N35: =ROUND(N11*'01_Assumptions'!$F$15,1) | O35: =SUM(C35:N35)
B36: Finance | C36: =ROUND(C12*'01_Assumptions'!$F$16,1) | D36: =ROUND(D12*'01_Assumptions'!$F$16,1) | E36: =ROUND(E12*'01_Assumptions'!$F$16,1) | F36: =ROUND(F12*'01_Assumptions'!$F$16,1) | G36: =ROUND(G12*'01_Assumptions'!$F$16,1) | H36: =ROUND(H12*'01_Assumptions'!$F$16,1) | I36: =ROUND(I12*'01_Assumptions'!$F$16,1) | J36: =ROUND(J12*'01_Assumptions'!$F$16,1) | ... N36: =ROUND(N12*'01_Assumptions'!$F$16,1) | O36: =SUM(C36:N36)
B37: HR | C37: =ROUND(C13*'01_Assumptions'!$F$17,1) | D37: =ROUND(D13*'01_Assumptions'!$F$17,1) | E37: =ROUND(E13*'01_Assumptions'!$F$17,1) | F37: =ROUND(F13*'01_Assumptions'!$F$17,1) | G37: =ROUND(G13*'01_Assumptions'!$F$17,1) | H37: =ROUND(H13*'01_Assumptions'!$F$17,1) | I37: =ROUND(I13*'01_Assumptions'!$F$17,1) | J37: =ROUND(J13*'01_Assumptions'!$F$17,1) | ... N37: =ROUND(N13*'01_Assumptions'!$F$17,1) | O37: =SUM(C37:N37)
B38: Quality / R&D | C38: =ROUND(C14*'01_Assumptions'!$F$18,1) | D38: =ROUND(D14*'01_Assumptions'!$F$18,1) | E38: =ROUND(E14*'01_Assumptions'!$F$18,1) | F38: =ROUND(F14*'01_Assumptions'!$F$18,1) | G38: =ROUND(G14*'01_Assumptions'!$F$18,1) | H38: =ROUND(H14*'01_Assumptions'!$F$18,1) | I38: =ROUND(I14*'01_Assumptions'!$F$18,1) | J38: =ROUND(J14*'01_Assumptions'!$F$18,1) | ... N38: =ROUND(N14*'01_Assumptions'!$F$18,1) | O38: =SUM(C38:N38)
B39: G&A / IT | C39: =ROUND(C15*'01_Assumptions'!$F$19,1) | D39: =ROUND(D15*'01_Assumptions'!$F$19,1) | E39: =ROUND(E15*'01_Assumptions'!$F$19,1) | F39: =ROUND(F15*'01_Assumptions'!$F$19,1) | G39: =ROUND(G15*'01_Assumptions'!$F$19,1) | H39: =ROUND(H15*'01_Assumptions'!$F$19,1) | I39: =ROUND(I15*'01_Assumptions'!$F$19,1) | J39: =ROUND(J15*'01_Assumptions'!$F$19,1) | ... N39: =ROUND(N15*'01_Assumptions'!$F$19,1) | O39: =SUM(C39:N39)
B40: Total | C40: =SUM(C32:C39) | D40: =SUM(D32:D39) | E40: =SUM(E32:E39) | F40: =SUM(F32:F39) | G40: =SUM(G32:G39) | H40: =SUM(H32:H39) | I40: =SUM(I32:I39) | J40: =SUM(J32:J39) | ... O40: =SUM(O32:O39)
B42: Other exits (restructuring / transfers-out) — input
C43: Jan-26 | D43: Feb-26 | E43: Mar-26 | F43: Apr-26 | G43: May-26 | H43: Jun-26 | I43: Jul-26 | J43: Aug-26 | K43: Sep-26 | L43: Oct-26 | M43: Nov-26 | N43: Dec-26 | O43: FY26
B44: Operations | C44: 0 | D44: 0 | E44: 1 | F44: 0 | G44: 0 | H44: 0 | I44: 0 | J44: 1 | K44: 0 | L44: 0 | M44: 0 | N44: 0 | O44: =SUM(C44:N44)
B45: Supply Chain | C45: 0 | D45: 0 | E45: 0 | F45: 0 | G45: 0 | H45: 0 | I45: 0 | J45: 0 | K45: 0 | L45: 0 | M45: 0 | N45: 0 | O45: =SUM(C45:N45)
B46: Sales | C46: 0 | D46: 0 | E46: 0 | F46: 0 | G46: 1 | H46: 0 | I46: 0 | J46: 0 | K46: 0 | L46: 0 | M46: 0 | N46: 0 | O46: =SUM(C46:N46)
...

Sheet 03_Cost_Bridge
B2: Loaded cost rollforward ($000s)
B3: Monthly cost = average FTE × (annual loaded / 12) × raise factor. Raise factor steps up in the merit month.
B5: Raise factor by month
C6: Jan-26 | D6: Feb-26 | E6: Mar-26 | F6: Apr-26 | G6: May-26 | H6: Jun-26 | I6: Jul-26 | J6: Aug-26 | K6: Sep-26 | L6: Oct-26 | M6: Nov-26 | N6: Dec-26 | O6: FY26
B7: Raise factor | C7: =IF(1>='01_Assumptions'!$C$7,1+'01_Assumptions'!$C$6,1) | D7: =IF(2>='01_Assumptions'!$C$7,1+'01_Assumptions'!$C$6,1) | E7: =IF(3>='01_Assumptions'!$C$7,1+'01_Assumptions'!$C$6,1) | F7: =IF(4>='01_Assumptions'!$C$7,1+'01_Assumptions'!$C$6,1) | G7: =IF(5>='01_Assumptions'!$C$7,1+'01_Assumptions'!$C$6,1) | H7: =IF(6>='01_Assumptions'!$C$7,1+'01_Assumptions'!$C$6,1) | I7: =IF(7>='01_Assumptions'!$C$7,1+'01_Assumptions'!$C$6,1) | J7: =IF(8>='01_Assumptions'!$C$7,1+'01_Assumptions'!$C$6,1) | K7: =IF(9>='01_Assumptions'!$C$7,1+'01_Assumptions'!$C$6,1) | L7: =IF(10>='01_Assumptions'!$C$7,1+'01_Assumptions'!$C$6,1) | M7: =IF(11>='01_Assumptions'!$C$7,1+'01_Assumptions'!$C$6,1) | N7: =IF(12>='01_Assumptions'!$C$7,1+'01_Assumptions'!$C$6,1) | O7: =N7
B9: Plan loaded cost by department ($000s)
C10: Jan-26 | D10: Feb-26 | E10: Mar-26 | F10: Apr-26 | G10: May-26 | H10: Jun-26 | I10: Jul-26 | J10: Aug-26 | K10: Sep-26 | L10: Oct-26 | M10: Nov-26 | N10: Dec-26 | O10: FY26 $
B11: Operations | C11: =(('02_Headcount_Plan'!C8+'02_Headcount_Plan'!C68)/2)*('01_Assumptions'!$D$12/12)*C$7 | D11: =(('02_Headcount_Plan'!D8+'02_Headcount_Plan'!D68)/2)*('01_Assumptions'!$D$12/12)*D$7 | E11: =(('02_Headcount_Plan'!E8+'02_Headcount_Plan'!E68)/2)*('01_Assumptions'!$D$12/12)*E$7 | F11: =(('02_Headcount_Plan'!F8+'02_Headcount_Plan'!F68)/2)*('01_Assumptions'!$D$12/12)*F$7 | G11: =(('02_Headcount_Plan'!G8+'02_Headcount_Plan'!G68)/2)*('01_Assumptions'!$D$12/12)*G$7 | H11: =(('02_Headcount_Plan'!H8+'02_Headcount_Plan'!H68)/2)*('01_Assumptions'!$D$12/12)*H$7 | I11: =(('02_Headcount_Plan'!I8+'02_Headcount_Plan'!I68)/2)*('01_Assumptions'!$D$12/12)*I$7 | J11: =(('02_Headcount_Plan'!J8+'02_Headcount_Plan'!J68)/2)*('01_Assumptions'!$D$12/12)*J$7 | ... N11: =(('02_Headcount_Plan'!N8+'02_Headcount_Plan'!N68)/2)*('01_Assumptions'!$D$12/12)*N$7 | O11: =SUM(C11:N11)
B12: Supply Chain | C12: =(('02_Headcount_Plan'!C9+'02_Headcount_Plan'!C69)/2)*('01_Assumptions'!$D$13/12)*C$7 | D12: =(('02_Headcount_Plan'!D9+'02_Headcount_Plan'!D69)/2)*('01_Assumptions'!$D$13/12)*D$7 | E12: =(('02_Headcount_Plan'!E9+'02_Headcount_Plan'!E69)/2)*('01_Assumptions'!$D$13/12)*E$7 | F12: =(('02_Headcount_Plan'!F9+'02_Headcount_Plan'!F69)/2)*('01_Assumptions'!$D$13/12)*F$7 | G12: =(('02_Headcount_Plan'!G9+'02_Headcount_Plan'!G69)/2)*('01_Assumptions'!$D$13/12)*G$7 | H12: =(('02_Headcount_Plan'!H9+'02_Headcount_Plan'!H69)/2)*('01_Assumptions'!$D$13/12)*H$7 | I12: =(('02_Headcount_Plan'!I9+'02_Headcount_Plan'!I69)/2)*('01_Assumptions'!$D$13/12)*I$7 | J12: =(('02_Headcount_Plan'!J9+'02_Headcount_Plan'!J69)/2)*('01_Assumptions'!$D$13/12)*J$7 | ... N12: =(('02_Headcount_Plan'!N9+'02_Headcount_Plan'!N69)/2)*('01_Assumptions'!$D$13/12)*N$7 | O12: =SUM(C12:N12)
B13: Sales | C13: =(('02_Headcount_Plan'!C10+'02_Headcount_Plan'!C70)/2)*('01_Assumptions'!$D$14/12)*C$7 | D13: =(('02_Headcount_Plan'!D10+'02_Headcount_Plan'!D70)/2)*('01_Assumptions'!$D$14/12)*D$7 | E13: =(('02_Headcount_Plan'!E10+'02_Headcount_Plan'!E70)/2)*('01_Assumptions'!$D$14/12)*E$7 | F13: =(('02_Headcount_Plan'!F10+'02_Headcount_Plan'!F70)/2)*('01_Assumptions'!$D$14/12)*F$7 | G13: =(('02_Headcount_Plan'!G10+'02_Headcount_Plan'!G70)/2)*('01_Assumptions'!$D$14/12)*G$7 | H13: =(('02_Headcount_Plan'!H10+'02_Headcount_Plan'!H70)/2)*('01_Assumptions'!$D$14/12)*H$7 | I13: =(('02_Headcount_Plan'!I10+'02_Headcount_Plan'!I70)/2)*('01_Assumptions'!$D$14/12)*I$7 | J13: =(('02_Headcount_Plan'!J10+'02_Headcount_Plan'!J70)/2)*('01_Assumptions'!$D$14/12)*J$7 | ... N13: =(('02_Headcount_Plan'!N10+'02_Headcount_Plan'!N70)/2)*('01_Assumptions'!$D$14/12)*N$7 | O13: =SUM(C13:N13)
B14: Marketing | C14: =(('02_Headcount_Plan'!C11+'02_Headcount_Plan'!C71)/2)*('01_Assumptions'!$D$15/12)*C$7 | D14: =(('02_Headcount_Plan'!D11+'02_Headcount_Plan'!D71)/2)*('01_Assumptions'!$D$15/12)*D$7 | E14: =(('02_Headcount_Plan'!E11+'02_Headcount_Plan'!E71)/2)*('01_Assumptions'!$D$15/12)*E$7 | F14: =(('02_Headcount_Plan'!F11+'02_Headcount_Plan'!F71)/2)*('01_Assumptions'!$D$15/12)*F$7 | G14: =(('02_Headcount_Plan'!G11+'02_Headcount_Plan'!G71)/2)*('01_Assumptions'!$D$15/12)*G$7 | H14: =(('02_Headcount_Plan'!H11+'02_Headcount_Plan'!H71)/2)*('01_Assumptions'!$D$15/12)*H$7 | I14: =(('02_Headcount_Plan'!I11+'02_Headcount_Plan'!I71)/2)*('01_Assumptions'!$D$15/12)*I$7 | J14: =(('02_Headcount_Plan'!J11+'02_Headcount_Plan'!J71)/2)*('01_Assumptions'!$D$15/12)*J$7 | ... N14: =(('02_Headcount_Plan'!N11+'02_Headcount_Plan'!N71)/2)*('01_Assumptions'!$D$15/12)*N$7 | O14: =SUM(C14:N14)
B15: Finance | C15: =(('02_Headcount_Plan'!C12+'02_Headcount_Plan'!C72)/2)*('01_Assumptions'!$D$16/12)*C$7 | D15: =(('02_Headcount_Plan'!D12+'02_Headcount_Plan'!D72)/2)*('01_Assumptions'!$D$16/12)*D$7 | E15: =(('02_Headcount_Plan'!E12+'02_Headcount_Plan'!E72)/2)*('01_Assumptions'!$D$16/12)*E$7 | F15: =(('02_Headcount_Plan'!F12+'02_Headcount_Plan'!F72)/2)*('01_Assumptions'!$D$16/12)*F$7 | G15: =(('02_Headcount_Plan'!G12+'02_Headcount_Plan'!G72)/2)*('01_Assumptions'!$D$16/12)*G$7 | H15: =(('02_Headcount_Plan'!H12+'02_Headcount_Plan'!H72)/2)*('01_Assumptions'!$D$16/12)*H$7 | I15: =(('02_Headcount_Plan'!I12+'02_Headcount_Plan'!I72)/2)*('01_Assumptions'!$D$16/12)*I$7 | J15: =(('02_Headcount_Plan'!J12+'02_Headcount_Plan'!J72)/2)*('01_Assumptions'!$D$16/12)*J$7 | ... N15: =(('02_Headcount_Plan'!N12+'02_Headcount_Plan'!N72)/2)*('01_Assumptions'!$D$16/12)*N$7 | O15: =SUM(C15:N15)
B16: HR | C16: =(('02_Headcount_Plan'!C13+'02_Headcount_Plan'!C73)/2)*('01_Assumptions'!$D$17/12)*C$7 | D16: =(('02_Headcount_Plan'!D13+'02_Headcount_Plan'!D73)/2)*('01_Assumptions'!$D$17/12)*D$7 | E16: =(('02_Headcount_Plan'!E13+'02_Headcount_Plan'!E73)/2)*('01_Assumptions'!$D$17/12)*E$7 | F16: =(('02_Headcount_Plan'!F13+'02_Headcount_Plan'!F73)/2)*('01_Assumptions'!$D$17/12)*F$7 | G16: =(('02_Headcount_Plan'!G13+'02_Headcount_Plan'!G73)/2)*('01_Assumptions'!$D$17/12)*G$7 | H16: =(('02_Headcount_Plan'!H13+'02_Headcount_Plan'!H73)/2)*('01_Assumptions'!$D$17/12)*H$7 | I16: =(('02_Headcount_Plan'!I13+'02_Headcount_Plan'!I73)/2)*('01_Assumptions'!$D$17/12)*I$7 | J16: =(('02_Headcount_Plan'!J13+'02_Headcount_Plan'!J73)/2)*('01_Assumptions'!$D$17/12)*J$7 | ... N16: =(('02_Headcount_Plan'!N13+'02_Headcount_Plan'!N73)/2)*('01_Assumptions'!$D$17/12)*N$7 | O16: =SUM(C16:N16)
B17: Quality / R&D | C17: =(('02_Headcount_Plan'!C14+'02_Headcount_Plan'!C74)/2)*('01_Assumptions'!$D$18/12)*C$7 | D17: =(('02_Headcount_Plan'!D14+'02_Headcount_Plan'!D74)/2)*('01_Assumptions'!$D$18/12)*D$7 | E17: =(('02_Headcount_Plan'!E14+'02_Headcount_Plan'!E74)/2)*('01_Assumptions'!$D$18/12)*E$7 | F17: =(('02_Headcount_Plan'!F14+'02_Headcount_Plan'!F74)/2)*('01_Assumptions'!$D$18/12)*F$7 | G17: =(('02_Headcount_Plan'!G14+'02_Headcount_Plan'!G74)/2)*('01_Assumptions'!$D$18/12)*G$7 | H17: =(('02_Headcount_Plan'!H14+'02_Headcount_Plan'!H74)/2)*('01_Assumptions'!$D$18/12)*H$7 | I17: =(('02_Headcount_Plan'!I14+'02_Headcount_Plan'!I74)/2)*('01_Assumptions'!$D$18/12)*I$7 | J17: =(('02_Headcount_Plan'!J14+'02_Headcount_Plan'!J74)/2)*('01_Assumptions'!$D$18/12)*J$7 | ... N17: =(('02_Headcount_Plan'!N14+'02_Headcount_Plan'!N74)/2)*('01_Assumptions'!$D$18/12)*N$7 | O17: =SUM(C17:N17)
B18: G&A / IT | C18: =(('02_Headcount_Plan'!C15+'02_Headcount_Plan'!C75)/2)*('01_Assumptions'!$D$19/12)*C$7 | D18: =(('02_Headcount_Plan'!D15+'02_Headcount_Plan'!D75)/2)*('01_Assumptions'!$D$19/12)*D$7 | E18: =(('02_Headcount_Plan'!E15+'02_Headcount_Plan'!E75)/2)*('01_Assumptions'!$D$19/12)*E$7 | F18: =(('02_Headcount_Plan'!F15+'02_Headcount_Plan'!F75)/2)*('01_Assumptions'!$D$19/12)*F$7 | G18: =(('02_Headcount_Plan'!G15+'02_Headcount_Plan'!G75)/2)*('01_Assumptions'!$D$19/12)*G$7 | H18: =(('02_Headcount_Plan'!H15+'02_Headcount_Plan'!H75)/2)*('01_Assumptions'!$D$19/12)*H$7 | I18: =(('02_Headcount_Plan'!I15+'02_Headcount_Plan'!I75)/2)*('01_Assumptions'!$D$19/12)*I$7 | J18: =(('02_Headcount_Plan'!J15+'02_Headcount_Plan'!J75)/2)*('01_Assumptions'!$D$19/12)*J$7 | ... N18: =(('02_Headcount_Plan'!N15+'02_Headcount_Plan'!N75)/2)*('01_Assumptions'!$D$19/12)*N$7 | O18: =SUM(C18:N18)
B19: Plan total | C19: =SUM(C11:C18) | D19: =SUM(D11:D18) | E19: =SUM(E11:E18) | F19: =SUM(F11:F18) | G19: =SUM(G11:G18) | H19: =SUM(H11:H18) | I19: =SUM(I11:I18) | J19: =SUM(J11:J18) | ... O19: =SUM(O11:O18)
B21: Forecast loaded cost by department ($000s) — FTE from 04_Reforecast
C22: Jan-26 | D22: Feb-26 | E22: Mar-26 | F22: Apr-26 | G22: May-26 | H22: Jun-26 | I22: Jul-26 | J22: Aug-26 | K22: Sep-26 | L22: Oct-26 | M22: Nov-26 | N22: Dec-26 | O22: FY26 $
B23: Operations | C23: =(('04_Reforecast'!C8+'04_Reforecast'!C68)/2)*('01_Assumptions'!$D$12/12)*C$7 | D23: =(('04_Reforecast'!D8+'04_Reforecast'!D68)/2)*('01_Assumptions'!$D$12/12)*D$7 | E23: =(('04_Reforecast'!E8+'04_Reforecast'!E68)/2)*('01_Assumptions'!$D$12/12)*E$7 | F23: =(('04_Reforecast'!F8+'04_Reforecast'!F68)/2)*('01_Assumptions'!$D$12/12)*F$7 | G23: =(('04_Reforecast'!G8+'04_Reforecast'!G68)/2)*('01_Assumptions'!$D$12/12)*G$7 | H23: =(('04_Reforecast'!H8+'04_Reforecast'!H68)/2)*('01_Assumptions'!$D$12/12)*H$7 | I23: =(('04_Reforecast'!I8+'04_Reforecast'!I68)/2)*('01_Assumptions'!$D$12/12)*I$7 | J23: =(('04_Reforecast'!J8+'04_Reforecast'!J68)/2)*('01_Assumptions'!$D$12/12)*J$7 | ... N23: =(('04_Reforecast'!N8+'04_Reforecast'!N68)/2)*('01_Assumptions'!$D$12/12)*N$7 | O23: =SUM(C23:N23)
B24: Supply Chain | C24: =(('04_Reforecast'!C9+'04_Reforecast'!C69)/2)*('01_Assumptions'!$D$13/12)*C$7 | D24: =(('04_Reforecast'!D9+'04_Reforecast'!D69)/2)*('01_Assumptions'!$D$13/12)*D$7 | E24: =(('04_Reforecast'!E9+'04_Reforecast'!E69)/2)*('01_Assumptions'!$D$13/12)*E$7 | F24: =(('04_Reforecast'!F9+'04_Reforecast'!F69)/2)*('01_Assumptions'!$D$13/12)*F$7 | G24: =(('04_Reforecast'!G9+'04_Reforecast'!G69)/2)*('01_Assumptions'!$D$13/12)*G$7 | H24: =(('04_Reforecast'!H9+'04_Reforecast'!H69)/2)*('01_Assumptions'!$D$13/12)*H$7 | I24: =(('04_Reforecast'!I9+'04_Reforecast'!I69)/2)*('01_Assumptions'!$D$13/12)*I$7 | J24: =(('04_Reforecast'!J9+'04_Reforecast'!J69)/2)*('01_Assumptions'!$D$13/12)*J$7 | ... N24: =(('04_Reforecast'!N9+'04_Reforecast'!N69)/2)*('01_Assumptions'!$D$13/12)*N$7 | O24: =SUM(C24:N24)
B25: Sales | C25: =(('04_Reforecast'!C10+'04_Reforecast'!C70)/2)*('01_Assumptions'!$D$14/12)*C$7 | D25: =(('04_Reforecast'!D10+'04_Reforecast'!D70)/2)*('01_Assumptions'!$D$14/12)*D$7 | E25: =(('04_Reforecast'!E10+'04_Reforecast'!E70)/2)*('01_Assumptions'!$D$14/12)*E$7 | F25: =(('04_Reforecast'!F10+'04_Reforecast'!F70)/2)*('01_Assumptions'!$D$14/12)*F$7 | G25: =(('04_Reforecast'!G10+'04_Reforecast'!G70)/2)*('01_Assumptions'!$D$14/12)*G$7 | H25: =(('04_Reforecast'!H10+'04_Reforecast'!H70)/2)*('01_Assumptions'!$D$14/12)*H$7 | I25: =(('04_Reforecast'!I10+'04_Reforecast'!I70)/2)*('01_Assumptions'!$D$14/12)*I$7 | J25: =(('04_Reforecast'!J10+'04_Reforecast'!J70)/2)*('01_Assumptions'!$D$14/12)*J$7 | ... N25: =(('04_Reforecast'!N10+'04_Reforecast'!N70)/2)*('01_Assumptions'!$D$14/12)*N$7 | O25: =SUM(C25:N25)
B26: Marketing | C26: =(('04_Reforecast'!C11+'04_Reforecast'!C71)/2)*('01_Assumptions'!$D$15/12)*C$7 | D26: =(('04_Reforecast'!D11+'04_Reforecast'!D71)/2)*('01_Assumptions'!$D$15/12)*D$7 | E26: =(('04_Reforecast'!E11+'04_Reforecast'!E71)/2)*('01_Assumptions'!$D$15/12)*E$7 | F26: =(('04_Reforecast'!F11+'04_Reforecast'!F71)/2)*('01_Assumptions'!$D$15/12)*F$7 | G26: =(('04_Reforecast'!G11+'04_Reforecast'!G71)/2)*('01_Assumptions'!$D$15/12)*G$7 | H26: =(('04_Reforecast'!H11+'04_Reforecast'!H71)/2)*('01_Assumptions'!$D$15/12)*H$7 | I26: =(('04_Reforecast'!I11+'04_Reforecast'!I71)/2)*('01_Assumptions'!$D$15/12)*I$7 | J26: =(('04_Reforecast'!J11+'04_Reforecast'!J71)/2)*('01_Assumptions'!$D$15/12)*J$7 | ... N26: =(('04_Reforecast'!N11+'04_Reforecast'!N71)/2)*('01_Assumptions'!$D$15/12)*N$7 | O26: =SUM(C26:N26)
B27: Finance | C27: =(('04_Reforecast'!C12+'04_Reforecast'!C72)/2)*('01_Assumptions'!$D$16/12)*C$7 | D27: =(('04_Reforecast'!D12+'04_Reforecast'!D72)/2)*('01_Assumptions'!$D$16/12)*D$7 | E27: =(('04_Reforecast'!E12+'04_Reforecast'!E72)/2)*('01_Assumptions'!$D$16/12)*E$7 | F27: =(('04_Reforecast'!F12+'04_Reforecast'!F72)/2)*('01_Assumptions'!$D$16/12)*F$7 | G27: =(('04_Reforecast'!G12+'04_Reforecast'!G72)/2)*('01_Assumptions'!$D$16/12)*G$7 | H27: =(('04_Reforecast'!H12+'04_Reforecast'!H72)/2)*('01_Assumptions'!$D$16/12)*H$7 | I27: =(('04_Reforecast'!I12+'04_Reforecast'!I72)/2)*('01_Assumptions'!$D$16/12)*I$7 | J27: =(('04_Reforecast'!J12+'04_Reforecast'!J72)/2)*('01_Assumptions'!$D$16/12)*J$7 | ... N27: =(('04_Reforecast'!N12+'04_Reforecast'!N72)/2)*('01_Assumptions'!$D$16/12)*N$7 | O27: =SUM(C27:N27)
B28: HR | C28: =(('04_Reforecast'!C13+'04_Reforecast'!C73)/2)*('01_Assumptions'!$D$17/12)*C$7 | D28: =(('04_Reforecast'!D13+'04_Reforecast'!D73)/2)*('01_Assumptions'!$D$17/12)*D$7 | E28: =(('04_Reforecast'!E13+'04_Reforecast'!E73)/2)*('01_Assumptions'!$D$17/12)*E$7 | F28: =(('04_Reforecast'!F13+'04_Reforecast'!F73)/2)*('01_Assumptions'!$D$17/12)*F$7 | G28: =(('04_Reforecast'!G13+'04_Reforecast'!G73)/2)*('01_Assumptions'!$D$17/12)*G$7 | H28: =(('04_Reforecast'!H13+'04_Reforecast'!H73)/2)*('01_Assumptions'!$D$17/12)*H$7 | I28: =(('04_Reforecast'!I13+'04_Reforecast'!I73)/2)*('01_Assumptions'!$D$17/12)*I$7 | J28: =(('04_Reforecast'!J13+'04_Reforecast'!J73)/2)*('01_Assumptions'!$D$17/12)*J$7 | ... N28: =(('04_Reforecast'!N13+'04_Reforecast'!N73)/2)*('01_Assumptions'!$D$17/12)*N$7 | O28: =SUM(C28:N28)
B29: Quality / R&D | C29: =(('04_Reforecast'!C14+'04_Reforecast'!C74)/2)*('01_Assumptions'!$D$18/12)*C$7 | D29: =(('04_Reforecast'!D14+'04_Reforecast'!D74)/2)*('01_Assumptions'!$D$18/12)*D$7 | E29: =(('04_Reforecast'!E14+'04_Reforecast'!E74)/2)*('01_Assumptions'!$D$18/12)*E$7 | F29: =(('04_Reforecast'!F14+'04_Reforecast'!F74)/2)*('01_Assumptions'!$D$18/12)*F$7 | G29: =(('04_Reforecast'!G14+'04_Reforecast'!G74)/2)*('01_Assumptions'!$D$18/12)*G$7 | H29: =(('04_Reforecast'!H14+'04_Reforecast'!H74)/2)*('01_Assumptions'!$D$18/12)*H$7 | I29: =(('04_Reforecast'!I14+'04_Reforecast'!I74)/2)*('01_Assumptions'!$D$18/12)*I$7 | J29: =(('04_Reforecast'!J14+'04_Reforecast'!J74)/2)*('01_Assumptions'!$D$18/12)*J$7 | ... N29: =(('04_Reforecast'!N14+'04_Reforecast'!N74)/2)*('01_Assumptions'!$D$18/12)*N$7 | O29: =SUM(C29:N29)
B30: G&A / IT | C30: =(('04_Reforecast'!C15+'04_Reforecast'!C75)/2)*('01_Assumptions'!$D$19/12)*C$7 | D30: =(('04_Reforecast'!D15+'04_Reforecast'!D75)/2)*('01_Assumptions'!$D$19/12)*D$7 | E30: =(('04_Reforecast'!E15+'04_Reforecast'!E75)/2)*('01_Assumptions'!$D$19/12)*E$7 | F30: =(('04_Reforecast'!F15+'04_Reforecast'!F75)/2)*('01_Assumptions'!$D$19/12)*F$7 | G30: =(('04_Reforecast'!G15+'04_Reforecast'!G75)/2)*('01_Assumptions'!$D$19/12)*G$7 | H30: =(('04_Reforecast'!H15+'04_Reforecast'!H75)/2)*('01_Assumptions'!$D$19/12)*H$7 | I30: =(('04_Reforecast'!I15+'04_Reforecast'!I75)/2)*('01_Assumptions'!$D$19/12)*I$7 | J30: =(('04_Reforecast'!J15+'04_Reforecast'!J75)/2)*('01_Assumptions'!$D$19/12)*J$7 | ... N30: =(('04_Reforecast'!N15+'04_Reforecast'!N75)/2)*('01_Assumptions'!$D$19/12)*N$7 | O30: =SUM(C30:N30)
B31: Forecast total | C31: =SUM(C23:C30) | D31: =SUM(D23:D30) | E31: =SUM(E23:E30) | F31: =SUM(F23:F30) | G31: =SUM(G23:G30) | H31: =SUM(H23:H30) | I31: =SUM(I23:I30) | J31: =SUM(J23:J30) | ... O31: =SUM(O23:O30)
B33: Variance (forecast − plan) $000s
C34: Jan-26 | D34: Feb-26 | E34: Mar-26 | F34: Apr-26 | G34: May-26 | H34: Jun-26 | I34: Jul-26 | J34: Aug-26 | K34: Sep-26 | L34: Oct-26 | M34: Nov-26 | N34: Dec-26 | O34: FY26 $
B35: Operations | C35: =C23-C11 | D35: =D23-D11 | E35: =E23-E11 | F35: =F23-F11 | G35: =G23-G11 | H35: =H23-H11 | I35: =I23-I11 | J35: =J23-J11 | ... O35: =O23-O11
B36: Supply Chain | C36: =C24-C12 | D36: =D24-D12 | E36: =E24-E12 | F36: =F24-F12 | G36: =G24-G12 | H36: =H24-H12 | I36: =I24-I12 | J36: =J24-J12 | ... O36: =O24-O12
B37: Sales | C37: =C25-C13 | D37: =D25-D13 | E37: =E25-E13 | F37: =F25-F13 | G37: =G25-G13 | H37: =H25-H13 | I37: =I25-I13 | J37: =J25-J13 | ... O37: =O25-O13
B38: Marketing | C38: =C26-C14 | D38: =D26-D14 | E38: =E26-E14 | F38: =F26-F14 | G38: =G26-G14 | H38: =H26-H14 | I38: =I26-I14 | J38: =J26-J14 | ... O38: =O26-O14
B39: Finance | C39: =C27-C15 | D39: =D27-D15 | E39: =E27-E15 | F39: =F27-F15 | G39: =G27-G15 | H39: =H27-H15 | I39: =I27-I15 | J39: =J27-J15 | ... O39: =O27-O15
B40: HR | C40: =C28-C16 | D40: =D28-D16 | E40: =E28-E16 | F40: =F28-F16 | G40: =G28-G16 | H40: =H28-H16 | I40: =I28-I16 | J40: =J28-J16 | ... O40: =O28-O16
B41: Quality / R&D | C41: =C29-C17 | D41: =D29-D17 | E41: =E29-E17 | F41: =F29-F17 | G41: =G29-G17 | H41: =H29-H17 | I41: =I29-I17 | J41: =J29-J17 | ... O41: =O29-O17
B42: G&A / IT | C42: =C30-C18 | D42: =D30-D18 | E42: =E30-E18 | F42: =F30-F18 | G42: =G30-G18 | H42: =H30-H18 | I42: =I30-I18 | J42: =J30-J18 | ... O42: =O30-O18
B43: Variance total | C43: =C31-C19 | D43: =D31-D19 | E43: =E31-E19 | F43: =F31-F19 | G43: =G31-G19 | H43: =H31-H19 | I43: =I31-I19 | J43: =J31-J19 | ... O43: =O31-O19
B45: FY cost bridge (plan) — illustrative, $000s
B46: Bridge step | C46: $000s
...

Sheet 04_Reforecast
B2: Reforecast — latest view vs original plan
B3: Same mechanics as the plan. Hires and other exits are the latest view (YTD actuals through the as-of month, then forecast).
B4: As-of month | C4: ='01_Assumptions'!D5
C5: =IF(1<='01_Assumptions'!$C$5,"Actual","Forecast") | D5: =IF(2<='01_Assumptions'!$C$5,"Actual","Forecast") | E5: =IF(3<='01_Assumptions'!$C$5,"Actual","Forecast") | F5: =IF(4<='01_Assumptions'!$C$5,"Actual","Forecast") | G5: =IF(5<='01_Assumptions'!$C$5,"Actual","Forecast") | H5: =IF(6<='01_Assumptions'!$C$5,"Actual","Forecast") | I5: =IF(7<='01_Assumptions'!$C$5,"Actual","Forecast") | J5: =IF(8<='01_Assumptions'!$C$5,"Actual","Forecast") | K5: =IF(9<='01_Assumptions'!$C$5,"Actual","Forecast") | L5: =IF(10<='01_Assumptions'!$C$5,"Actual","Forecast") | M5: =IF(11<='01_Assumptions'!$C$5,"Actual","Forecast") | N5: =IF(12<='01_Assumptions'!$C$5,"Actual","Forecast")
B6: Opening FTE (latest view)
C7: Jan-26 | D7: Feb-26 | E7: Mar-26 | F7: Apr-26 | G7: May-26 | H7: Jun-26 | I7: Jul-26 | J7: Aug-26 | K7: Sep-26 | L7: Oct-26 | M7: Nov-26 | N7: Dec-26 | O7: FY26
B8: Operations | C8: ='01_Assumptions'!C12 | D8: =C68 | E8: =D68 | F8: =E68 | G8: =F68 | H8: =G68 | I8: =H68 | J8: =I68 | K8: =J68 | ... N8: =M68 | O8: =C8
B9: Supply Chain | C9: ='01_Assumptions'!C13 | D9: =C69 | E9: =D69 | F9: =E69 | G9: =F69 | H9: =G69 | I9: =H69 | J9: =I69 | K9: =J69 | ... N9: =M69 | O9: =C9
B10: Sales | C10: ='01_Assumptions'!C14 | D10: =C70 | E10: =D70 | F10: =E70 | G10: =F70 | H10: =G70 | I10: =H70 | J10: =I70 | K10: =J70 | ... N10: =M70 | O10: =C10
B11: Marketing | C11: ='01_Assumptions'!C15 | D11: =C71 | E11: =D71 | F11: =E71 | G11: =F71 | H11: =G71 | I11: =H71 | J11: =I71 | K11: =J71 | ... N11: =M71 | O11: =C11
B12: Finance | C12: ='01_Assumptions'!C16 | D12: =C72 | E12: =D72 | F12: =E72 | G12: =F72 | H12: =G72 | I12: =H72 | J12: =I72 | K12: =J72 | ... N12: =M72 | O12: =C12
B13: HR | C13: ='01_Assumptions'!C17 | D13: =C73 | E13: =D73 | F13: =E73 | G13: =F73 | H13: =G73 | I13: =H73 | J13: =I73 | K13: =J73 | ... N13: =M73 | O13: =C13
B14: Quality / R&D | C14: ='01_Assumptions'!C18 | D14: =C74 | E14: =D74 | F14: =E74 | G14: =F74 | H14: =G74 | I14: =H74 | J14: =I74 | K14: =J74 | ... N14: =M74 | O14: =C14
B15: G&A / IT | C15: ='01_Assumptions'!C19 | D15: =C75 | E15: =D75 | F15: =E75 | G15: =F75 | H15: =G75 | I15: =H75 | J15: =I75 | K15: =J75 | ... N15: =M75 | O15: =C15
B16: Total | C16: =SUM(C8:C15) | D16: =SUM(D8:D15) | E16: =SUM(E8:E15) | F16: =SUM(F8:F15) | G16: =SUM(G8:G15) | H16: =SUM(H8:H15) | I16: =SUM(I8:I15) | J16: =SUM(J8:J15) | ... O16: =SUM(O8:O15)
B18: Hires (starts) — latest view, input
C19: Jan-26 | D19: Feb-26 | E19: Mar-26 | F19: Apr-26 | G19: May-26 | H19: Jun-26 | I19: Jul-26 | J19: Aug-26 | K19: Sep-26 | L19: Oct-26 | M19: Nov-26 | N19: Dec-26 | O19: FY26
B20: Operations | C20: 2 | D20: 1 | E20: 2 | F20: 1 | G20: 2 | H20: 1 | I20: 2 | J20: 2 | K20: 1 | L20: 2 | M20: 2 | N20: 1 | O20: =SUM(C20:N20)
B21: Supply Chain | C21: 1 | D21: 0 | E21: 1 | F21: 0 | G21: 1 | H21: 1 | I21: 1 | J21: 1 | K21: 0 | L21: 1 | M21: 1 | N21: 0 | O21: =SUM(C21:N21)
B22: Sales | C22: 1 | D22: 0 | E22: 1 | F22: 1 | G22: 1 | H22: 1 | I22: 2 | J22: 0 | K22: 1 | L22: 1 | M22: 0 | N22: 1 | O22: =SUM(C22:N22)
B23: Marketing | C23: 0 | D23: 1 | E23: 0 | F23: 0 | G23: 0 | H23: 1 | I23: 0 | J23: 1 | K23: 0 | L23: 0 | M23: 0 | N23: 0 | O23: =SUM(C23:N23)
B24: Finance | C24: 0 | D24: 0 | E24: 1 | F24: 0 | G24: 0 | H24: 0 | I24: 0 | J24: 0 | K24: 0 | L24: 1 | M24: 0 | N24: 0 | O24: =SUM(C24:N24)
B25: HR | C25: 0 | D25: 0 | E25: 0 | F25: 1 | G25: 0 | H25: 0 | I25: 0 | J25: 0 | K25: 0 | L25: 0 | M25: 0 | N25: 0 | O25: =SUM(C25:N25)
B26: Quality / R&D | C26: 1 | D26: 0 | E26: 0 | F26: 0 | G26: 1 | H26: 0 | I26: 1 | J26: 0 | K26: 0 | L26: 0 | M26: 0 | N26: 0 | O26: =SUM(C26:N26)
B27: G&A / IT | C27: 0 | D27: 0 | E27: 0 | F27: 1 | G27: 0 | H27: 0 | I27: 0 | J27: 0 | K27: 1 | L27: 0 | M27: 0 | N27: 0 | O27: =SUM(C27:N27)
B28: Total | C28: =SUM(C20:C27) | D28: =SUM(D20:D27) | E28: =SUM(E20:E27) | F28: =SUM(F20:F27) | G28: =SUM(G20:G27) | H28: =SUM(H20:H27) | I28: =SUM(I20:I27) | J28: =SUM(J20:J27) | ... O28: =SUM(O20:O27)
B30: Modeled attrition exits = ROUND(opening × monthly attrition, 1)
C31: Jan-26 | D31: Feb-26 | E31: Mar-26 | F31: Apr-26 | G31: May-26 | H31: Jun-26 | I31: Jul-26 | J31: Aug-26 | K31: Sep-26 | L31: Oct-26 | M31: Nov-26 | N31: Dec-26 | O31: FY26
B32: Operations | C32: =ROUND(C8*'01_Assumptions'!$F$12,1) | D32: =ROUND(D8*'01_Assumptions'!$F$12,1) | E32: =ROUND(E8*'01_Assumptions'!$F$12,1) | F32: =ROUND(F8*'01_Assumptions'!$F$12,1) | G32: =ROUND(G8*'01_Assumptions'!$F$12,1) | H32: =ROUND(H8*'01_Assumptions'!$F$12,1) | I32: =ROUND(I8*'01_Assumptions'!$F$12,1) | J32: =ROUND(J8*'01_Assumptions'!$F$12,1) | ... N32: =ROUND(N8*'01_Assumptions'!$F$12,1) | O32: =SUM(C32:N32)
B33: Supply Chain | C33: =ROUND(C9*'01_Assumptions'!$F$13,1) | D33: =ROUND(D9*'01_Assumptions'!$F$13,1) | E33: =ROUND(E9*'01_Assumptions'!$F$13,1) | F33: =ROUND(F9*'01_Assumptions'!$F$13,1) | G33: =ROUND(G9*'01_Assumptions'!$F$13,1) | H33: =ROUND(H9*'01_Assumptions'!$F$13,1) | I33: =ROUND(I9*'01_Assumptions'!$F$13,1) | J33: =ROUND(J9*'01_Assumptions'!$F$13,1) | ... N33: =ROUND(N9*'01_Assumptions'!$F$13,1) | O33: =SUM(C33:N33)
B34: Sales | C34: =ROUND(C10*'01_Assumptions'!$F$14,1) | D34: =ROUND(D10*'01_Assumptions'!$F$14,1) | E34: =ROUND(E10*'01_Assumptions'!$F$14,1) | F34: =ROUND(F10*'01_Assumptions'!$F$14,1) | G34: =ROUND(G10*'01_Assumptions'!$F$14,1) | H34: =ROUND(H10*'01_Assumptions'!$F$14,1) | I34: =ROUND(I10*'01_Assumptions'!$F$14,1) | J34: =ROUND(J10*'01_Assumptions'!$F$14,1) | ... N34: =ROUND(N10*'01_Assumptions'!$F$14,1) | O34: =SUM(C34:N34)
B35: Marketing | C35: =ROUND(C11*'01_Assumptions'!$F$15,1) | D35: =ROUND(D11*'01_Assumptions'!$F$15,1) | E35: =ROUND(E11*'01_Assumptions'!$F$15,1) | F35: =ROUND(F11*'01_Assumptions'!$F$15,1) | G35: =ROUND(G11*'01_Assumptions'!$F$15,1) | H35: =ROUND(H11*'01_Assumptions'!$F$15,1) | I35: =ROUND(I11*'01_Assumptions'!$F$15,1) | J35: =ROUND(J11*'01_Assumptions'!$F$15,1) | ... N35: =ROUND(N11*'01_Assumptions'!$F$15,1) | O35: =SUM(C35:N35)
B36: Finance | C36: =ROUND(C12*'01_Assumptions'!$F$16,1) | D36: =ROUND(D12*'01_Assumptions'!$F$16,1) | E36: =ROUND(E12*'01_Assumptions'!$F$16,1) | F36: =ROUND(F12*'01_Assumptions'!$F$16,1) | G36: =ROUND(G12*'01_Assumptions'!$F$16,1) | H36: =ROUND(H12*'01_Assumptions'!$F$16,1) | I36: =ROUND(I12*'01_Assumptions'!$F$16,1) | J36: =ROUND(J12*'01_Assumptions'!$F$16,1) | ... N36: =ROUND(N12*'01_Assumptions'!$F$16,1) | O36: =SUM(C36:N36)
B37: HR | C37: =ROUND(C13*'01_Assumptions'!$F$17,1) | D37: =ROUND(D13*'01_Assumptions'!$F$17,1) | E37: =ROUND(E13*'01_Assumptions'!$F$17,1) | F37: =ROUND(F13*'01_Assumptions'!$F$17,1) | G37: =ROUND(G13*'01_Assumptions'!$F$17,1) | H37: =ROUND(H13*'01_Assumptions'!$F$17,1) | I37: =ROUND(I13*'01_Assumptions'!$F$17,1) | J37: =ROUND(J13*'01_Assumptions'!$F$17,1) | ... N37: =ROUND(N13*'01_Assumptions'!$F$17,1) | O37: =SUM(C37:N37)
B38: Quality / R&D | C38: =ROUND(C14*'01_Assumptions'!$F$18,1) | D38: =ROUND(D14*'01_Assumptions'!$F$18,1) | E38: =ROUND(E14*'01_Assumptions'!$F$18,1) | F38: =ROUND(F14*'01_Assumptions'!$F$18,1) | G38: =ROUND(G14*'01_Assumptions'!$F$18,1) | H38: =ROUND(H14*'01_Assumptions'!$F$18,1) | I38: =ROUND(I14*'01_Assumptions'!$F$18,1) | J38: =ROUND(J14*'01_Assumptions'!$F$18,1) | ... N38: =ROUND(N14*'01_Assumptions'!$F$18,1) | O38: =SUM(C38:N38)
B39: G&A / IT | C39: =ROUND(C15*'01_Assumptions'!$F$19,1) | D39: =ROUND(D15*'01_Assumptions'!$F$19,1) | E39: =ROUND(E15*'01_Assumptions'!$F$19,1) | F39: =ROUND(F15*'01_Assumptions'!$F$19,1) | G39: =ROUND(G15*'01_Assumptions'!$F$19,1) | H39: =ROUND(H15*'01_Assumptions'!$F$19,1) | I39: =ROUND(I15*'01_Assumptions'!$F$19,1) | J39: =ROUND(J15*'01_Assumptions'!$F$19,1) | ... N39: =ROUND(N15*'01_Assumptions'!$F$19,1) | O39: =SUM(C39:N39)
B40: Total | C40: =SUM(C32:C39) | D40: =SUM(D32:D39) | E40: =SUM(E32:E39) | F40: =SUM(F32:F39) | G40: =SUM(G32:G39) | H40: =SUM(H32:H39) | I40: =SUM(I32:I39) | J40: =SUM(J32:J39) | ... O40: =SUM(O32:O39)
B42: Other exits — latest view, input
C43: Jan-26 | D43: Feb-26 | E43: Mar-26 | F43: Apr-26 | G43: May-26 | H43: Jun-26 | I43: Jul-26 | J43: Aug-26 | K43: Sep-26 | L43: Oct-26 | M43: Nov-26 | N43: Dec-26 | O43: FY26
B44: Operations | C44: 0 | D44: 1 | E44: 0 | F44: 0 | G44: 0 | H44: 1 | I44: 0 | J44: 1 | K44: 0 | L44: 0 | M44: 0 | N44: 0 | O44: =SUM(C44:N44)
...

Sheet 05_Dashboard
B2: Headcount dashboard
B3: As-of month | C3: ='01_Assumptions'!D5 | E3: Yellow + blue = inputs (on other tabs). This page is formulas.
B5: Ending FTE (latest) | E5: FY loaded cost ($000s) | H5: YTD net / pipeline | K5: Attrition (annualized)
B6: Actual / forecast | C6: =INDEX('04_Reforecast'!C76:N76,1,'01_Assumptions'!$C$5) | E6: Forecast FY $ | F6: ='03_Cost_Bridge'!O31 | H6: YTD hires (latest) | I6: =SUMIF('04_Reforecast'!C5:N5,"Actual",'04_Reforecast'!C28:N28) | K6: As-of month | L6: =IF(INDEX('04_Reforecast'!C16:N16,1,'01_Assumptions'!$C$5)=0,0,INDEX('04_Reforecast'!C64:N64,1,'01_Assumptions'!$C$5)/INDEX('04_Reforecast'!C16:N16,1,'01_Assumptions'!$C$5)*12)
B7: Original plan | C7: =INDEX('02_Headcount_Plan'!C76:N76,1,'01_Assumptions'!$C$5) | E7: Plan FY $ | F7: ='03_Cost_Bridge'!O19 | H7: YTD exits (latest) | I7: =SUMIF('04_Reforecast'!C5:N5,"Actual",'04_Reforecast'!C64:N64) | K7: Company target | L7: ='01_Assumptions'!E20
B8: Var vs plan | C8: =C6-C7 | E8: Var $ | F8: =F6-F7 | H8: Open reqs | I8: ='01_Assumptions'!G20 | K8: Hire lead time (mo) | L8: ='01_Assumptions'!C8
B10: Monthly totals (feeds charts)
B11: Metric | C11: Jan-26 | D11: Feb-26 | E11: Mar-26 | F11: Apr-26 | G11: May-26 | H11: Jun-26 | I11: Jul-26 | J11: Aug-26 | K11: Sep-26 | L11: Oct-26 | M11: Nov-26 | N11: Dec-26
B12: Plan ending FTE | C12: ='02_Headcount_Plan'!C76 | D12: ='02_Headcount_Plan'!D76 | E12: ='02_Headcount_Plan'!E76 | F12: ='02_Headcount_Plan'!F76 | G12: ='02_Headcount_Plan'!G76 | H12: ='02_Headcount_Plan'!H76 | I12: ='02_Headcount_Plan'!I76 | J12: ='02_Headcount_Plan'!J76 | ... N12: ='02_Headcount_Plan'!N76
B13: Latest ending FTE | C13: ='04_Reforecast'!C76 | D13: ='04_Reforecast'!D76 | E13: ='04_Reforecast'!E76 | F13: ='04_Reforecast'!F76 | G13: ='04_Reforecast'!G76 | H13: ='04_Reforecast'!H76 | I13: ='04_Reforecast'!I76 | J13: ='04_Reforecast'!J76 | ... N13: ='04_Reforecast'!N76
B14: Plan monthly $ | C14: ='03_Cost_Bridge'!C19 | D14: ='03_Cost_Bridge'!D19 | E14: ='03_Cost_Bridge'!E19 | F14: ='03_Cost_Bridge'!F19 | G14: ='03_Cost_Bridge'!G19 | H14: ='03_Cost_Bridge'!H19 | I14: ='03_Cost_Bridge'!I19 | J14: ='03_Cost_Bridge'!J19 | ... N14: ='03_Cost_Bridge'!N19
B15: Latest monthly $ | C15: ='03_Cost_Bridge'!C31 | D15: ='03_Cost_Bridge'!D31 | E15: ='03_Cost_Bridge'!E31 | F15: ='03_Cost_Bridge'!F31 | G15: ='03_Cost_Bridge'!G31 | H15: ='03_Cost_Bridge'!H31 | I15: ='03_Cost_Bridge'!I31 | J15: ='03_Cost_Bridge'!J31 | ... N15: ='03_Cost_Bridge'!N31
B16: Status | C16: ='04_Reforecast'!C5 | D16: ='04_Reforecast'!D5 | E16: ='04_Reforecast'!E5 | F16: ='04_Reforecast'!F5 | G16: ='04_Reforecast'!G5 | H16: ='04_Reforecast'!H5 | I16: ='04_Reforecast'!I5 | J16: ='04_Reforecast'!J5 | ... N16: ='04_Reforecast'!N5
B34: Year-end FTE by department
B35: Department | C35: Plan | D35: Latest
B36: Operations | C36: ='04_Reforecast'!C84 | D36: ='04_Reforecast'!D84
B37: Supply Chain | C37: ='04_Reforecast'!C85 | D37: ='04_Reforecast'!D85
B38: Sales | C38: ='04_Reforecast'!C86 | D38: ='04_Reforecast'!D86
B39: Marketing | C39: ='04_Reforecast'!C87 | D39: ='04_Reforecast'!D87
B40: Finance | C40: ='04_Reforecast'!C88 | D40: ='04_Reforecast'!D88
B41: HR | C41: ='04_Reforecast'!C89 | D41: ='04_Reforecast'!D89
B42: Quality / R&D | C42: ='04_Reforecast'!C90 | D42: ='04_Reforecast'!D90
B43: G&A / IT | C43: ='04_Reforecast'!C91 | D43: ='04_Reforecast'!D91
B46: Toggle the as-of month on Assumptions to walk the latest view from YTD actuals into the remaining-year forecast.

Sheet 06_Data_Dictionary
B2: Data dictionary
B3: Field definitions so another analyst can inherit the file.
B5: Field | C5: Tab | D5: Definition
B6: As-of / toggle month | C6: 01_Assumptions | D6: Month through which the reforecast holds YTD actuals. Later months are forecast. Dashboard INDEX uses this.
B7: Merit / raise % | C7: 01_Assumptions | D7: Company-wide loaded-cost step-up. Applied from the raise-effective month onward.
B8: Raise effective month | C8: 01_Assumptions | D8: First month the merit is in the run-rate (April in the sample).
B9: Hire lead time | C9: 01_Assumptions | D9: Months from approved req to start. Hires in the plan are booked in the start month.
B10: Opening FTE | C10: 01_Assumptions | D10: 1 Jan 2026 heads by department. Seeds January opening of both plan and reforecast.
B11: Annual loaded cost | C11: 01_Assumptions | D11: Fully loaded $000s per FTE per year (salary, benefits, taxes, typical bonus).
B12: Annual attrition % | C12: 01_Assumptions | D12: Expected voluntary/involuntary turnover. Monthly rate = annual ÷ 12.
B13: Open reqs | C13: 01_Assumptions | D13: Snapshot of approved unfilled requisitions (pipeline), not yet started.
B14: Hires (starts) | C14: 02_Headcount_Plan / 04_Reforecast | D14: Input. Heads that begin that month.
B15: Modeled attrition exits | C15: 02_Headcount_Plan / 04_Reforecast | D15: ROUND(opening FTE × monthly attrition, 1). Driven by the assumption rate.
B16: Other exits | C16: 02_Headcount_Plan / 04_Reforecast | D16: Input. Restructuring, transfers-out, or one-off exits on top of attrition.
... B23: Units | C23: All | D23: FTE in heads (one decimal). Cost in $000s. Rates in %.
B26: All sample numbers are fictional. Built for a public GitHub portfolio — no employer data.
